Mon Dec 16 18:55:08 CET 2024
NVIDIA A100-SXM4-40GB
2024-12-16 18:55:13.718616: W external/xla/xla/service/gpu/nvptx_compiler.cc:836] The NVIDIA driver's CUDA version is 12.5 which is older than the PTX compiler version (12.6.85). Because the driver is older than the PTX compiler version, XLA is disabling parallel compilation, which may slow down compilation. You should update your NVIDIA driver or use the NVIDIA-provided CUDA forward compatibility packages.
Warning: weights not properly specified, assuming constant weights instead.
GPU found?
[CudaDevice(id=0)]
Fixed params loaded inside the MicroToMacroTransform:
    E_sat: -16.0
Fixed params loaded inside the MicroToMacroTransform:
    E_sat: -16.0
Loading data necessary for the event GW170817
Not sampling PREX or CREX data now
Sanity checking: likelihoods_list = [<paper_jose.utils.GWlikelihood_with_masses object at 0x1494bc329780>, <paper_jose.utils.RadioTimingLikelihood object at 0x1494bba769e0>, <paper_jose.utils.RadioTimingLikelihood object at 0x1494bbb6fb50>, <paper_jose.utils.RadioTimingLikelihood object at 0x1494baeb7df0>]
len(likelihoods_list) = 4
We are going to give these kwargs to Jim:
{'n_loop_training': 10, 'n_loop_production': 20, 'n_chains': 500, 'n_local_steps': 2, 'n_global_steps': 10, 'n_epochs': 10, 'train_thinning': 1, 'output_thinning': 1}
We are going to sample the following parameters:
['E_sym', 'L_sym', 'K_sym', 'Q_sym', 'Z_sym', 'K_sat', 'Q_sat', 'Z_sat', 'nbreak', 'n_CSE_0_u', 'cs2_CSE_0', 'n_CSE_1_u', 'cs2_CSE_1', 'n_CSE_2_u', 'cs2_CSE_2', 'n_CSE_3_u', 'cs2_CSE_3', 'n_CSE_4_u', 'cs2_CSE_4', 'n_CSE_5_u', 'cs2_CSE_5', 'n_CSE_6_u', 'cs2_CSE_6', 'n_CSE_7_u', 'cs2_CSE_7', 'cs2_CSE_8', 'mass_1_GW170817', 'mass_2_GW170817']
No sample transforms provided. Using prior parameters as sampling parameters
['n_dim', 'n_chains', 'n_local_steps', 'n_global_steps', 'n_loop', 'output_thinning', 'verbose']
Global Tuning:   0%|          | 0/10 [00:00<?, ?it/s]Global Tuning:  10%|█         | 1/10 [02:14<20:13, 134.86s/it]Global Tuning:  20%|██        | 2/10 [02:54<10:30, 78.80s/it] jax.pure_callback failed
Traceback (most recent call last):
  File "/home/twouters2/miniconda3/envs/jose/lib/python3.10/site-packages/jax/_src/callback.py", line 86, in pure_callback_impl
    return tree_util.tree_map(np.asarray, callback(*args))
  File "/home/twouters2/miniconda3/envs/jose/lib/python3.10/site-packages/jax/_src/callback.py", line 64, in __call__
    return tree_util.tree_leaves(self.callback_func(*args, **kwargs))
  File "/home/twouters2/miniconda3/envs/jose/lib/python3.10/site-packages/equinox/_errors.py", line 89, in raises
    raise _EquinoxRuntimeError(
equinox._errors._EquinoxRuntimeError: The maximum number of solver steps was reached. Try increasing `max_steps`.


--------------------
An error occurred during the runtime of your JAX program! Unfortunately you do not appear to be using `equinox.filter_jit` (perhaps you are using `jax.jit` instead?) and so further information about the error cannot be displayed. (Probably you are seeing a very large but uninformative error message right now.) Please wrap your program with `equinox.filter_jit`.
--------------------

E1216 18:59:47.739259 3615436 pjrt_stream_executor_client.cc:3067] Execution of replica 0 failed: INTERNAL: CustomCall failed: CpuCallback error: Traceback (most recent call last):
  File "/gpfs/home6/twouters2/projects/jax_tov_eos/paper_jose/src/paper_jose/inference/inference.py", line 355, in <module>
  File "/gpfs/home6/twouters2/projects/jax_tov_eos/paper_jose/src/paper_jose/inference/inference.py", line 295, in main
  File "/gpfs/home6/twouters2/projects/jax_tov_eos/jim/src/jimgw/jim.py", line 119, in sample
  File "/gpfs/home6/twouters2/projects/jax_tov_eos/flowMC/src/flowMC/Sampler.py", line 204, in sample
  File "/gpfs/home6/twouters2/projects/jax_tov_eos/flowMC/src/flowMC/strategy/global_tuning.py", line 92, in __call__
  File "/gpfs/home6/twouters2/projects/jax_tov_eos/flowMC/src/flowMC/proposal/MALA.py", line 161, in sample
  File "/home/twouters2/miniconda3/envs/jose/lib/python3.10/site-packages/jax/_src/traceback_util.py", line 180, in reraise_with_filtered_traceback
  File "/home/twouters2/miniconda3/envs/jose/lib/python3.10/site-packages/jax/_src/pjit.py", line 332, in cache_miss
  File "/home/twouters2/miniconda3/envs/jose/lib/python3.10/site-packages/jax/_src/pjit.py", line 190, in _python_pjit_helper
  File "/home/twouters2/miniconda3/envs/jose/lib/python3.10/site-packages/jax/_src/core.py", line 2739, in bind
  File "/home/twouters2/miniconda3/envs/jose/lib/python3.10/site-packages/jax/_src/core.py", line 433, in bind_with_trace
  File "/home/twouters2/miniconda3/envs/jose/lib/python3.10/site-packages/jax/_src/core.py", line 939, in process_primitive
  File "/home/twouters2/miniconda3/envs/jose/lib/python3.10/site-packages/jax/_src/pjit.py", line 1730, in _pjit_call_impl
  File "/home/twouters2/miniconda3/envs/jose/lib/python3.10/site-packages/jax/_src/pjit.py", line 1712, in call_impl_cache_miss
  File "/home/twouters2/miniconda3/envs/jose/lib/python3.10/site-packages/jax/_src/pjit.py", line 1666, in _pjit_call_impl_python
  File "/home/twouters2/miniconda3/envs/jose/lib/python3.10/site-packages/jax/_src/profiler.py", line 336, in wrapper
  File "/home/twouters2/miniconda3/envs/jose/lib/python3.10/site-packages/jax/_src/interpreters/pxla.py", line 1239, in __call__
  File "/home/twouters2/miniconda3/envs/jose/lib/python3.10/site-packages/jax/_src/interpreters/mlir.py", line 2656, in _wrapped_callback
  File "/home/twouters2/miniconda3/envs/jose/lib/python3.10/site-packages/jax/_src/callback.py", line 228, in _callback
  File "/home/twouters2/miniconda3/envs/jose/lib/python3.10/site-packages/jax/_src/callback.py", line 89, in pure_callback_impl
  File "/home/twouters2/miniconda3/envs/jose/lib/python3.10/site-packages/jax/_src/callback.py", line 64, in __call__
  File "/home/twouters2/miniconda3/envs/jose/lib/python3.10/site-packages/equinox/_errors.py", line 89, in raises
_EquinoxRuntimeError: The maximum number of solver steps was reached. Try increasing `max_steps`.


--------------------
An error occurred during the runtime of your JAX program! Unfortunately you do not appear to be using `equinox.filter_jit` (perhaps you are using `jax.jit` instead?) and so further information about the error cannot be displayed. (Probably you are seeing a very large but uninformative error message right now.) Please wrap your program with `equinox.filter_jit`.
--------------------

Global Tuning:  20%|██        | 2/10 [03:29<13:59, 104.90s/it]
Compiling MALA body
jax.errors.SimplifiedTraceback: For simplicity, JAX has removed its internal frames from the traceback of the following exception. Set JAX_TRACEBACK_FILTERING=off to include these.

The above exception was the direct cause of the following exception:

Traceback (most recent call last):
  File "/gpfs/home6/twouters2/projects/jax_tov_eos/paper_jose/src/paper_jose/inference/inference.py", line 355, in <module>
    main(args)
  File "/gpfs/home6/twouters2/projects/jax_tov_eos/paper_jose/src/paper_jose/inference/inference.py", line 295, in main
    jim.sample(jax.random.PRNGKey(11))
  File "/gpfs/home6/twouters2/projects/jax_tov_eos/jim/src/jimgw/jim.py", line 119, in sample
    self.sampler.sample(initial_position, None)  # type: ignore
  File "/gpfs/home6/twouters2/projects/jax_tov_eos/flowMC/src/flowMC/Sampler.py", line 204, in sample
    ) = strategy(
  File "/gpfs/home6/twouters2/projects/jax_tov_eos/flowMC/src/flowMC/strategy/global_tuning.py", line 92, in __call__
    ) = local_sampler.sample(
  File "/gpfs/home6/twouters2/projects/jax_tov_eos/flowMC/src/flowMC/proposal/MALA.py", line 161, in sample
    state = self.update_vmap(i, state)
jaxlib.xla_extension.XlaRuntimeError: INTERNAL: CustomCall failed: CpuCallback error: Traceback (most recent call last):
  File "/gpfs/home6/twouters2/projects/jax_tov_eos/paper_jose/src/paper_jose/inference/inference.py", line 355, in <module>
  File "/gpfs/home6/twouters2/projects/jax_tov_eos/paper_jose/src/paper_jose/inference/inference.py", line 295, in main
  File "/gpfs/home6/twouters2/projects/jax_tov_eos/jim/src/jimgw/jim.py", line 119, in sample
  File "/gpfs/home6/twouters2/projects/jax_tov_eos/flowMC/src/flowMC/Sampler.py", line 204, in sample
  File "/gpfs/home6/twouters2/projects/jax_tov_eos/flowMC/src/flowMC/strategy/global_tuning.py", line 92, in __call__
  File "/gpfs/home6/twouters2/projects/jax_tov_eos/flowMC/src/flowMC/proposal/MALA.py", line 161, in sample
  File "/home/twouters2/miniconda3/envs/jose/lib/python3.10/site-packages/jax/_src/traceback_util.py", line 180, in reraise_with_filtered_traceback
  File "/home/twouters2/miniconda3/envs/jose/lib/python3.10/site-packages/jax/_src/pjit.py", line 332, in cache_miss
  File "/home/twouters2/miniconda3/envs/jose/lib/python3.10/site-packages/jax/_src/pjit.py", line 190, in _python_pjit_helper
  File "/home/twouters2/miniconda3/envs/jose/lib/python3.10/site-packages/jax/_src/core.py", line 2739, in bind
  File "/home/twouters2/miniconda3/envs/jose/lib/python3.10/site-packages/jax/_src/core.py", line 433, in bind_with_trace
  File "/home/twouters2/miniconda3/envs/jose/lib/python3.10/site-packages/jax/_src/core.py", line 939, in process_primitive
  File "/home/twouters2/miniconda3/envs/jose/lib/python3.10/site-packages/jax/_src/pjit.py", line 1730, in _pjit_call_impl
  File "/home/twouters2/miniconda3/envs/jose/lib/python3.10/site-packages/jax/_src/pjit.py", line 1712, in call_impl_cache_miss
  File "/home/twouters2/miniconda3/envs/jose/lib/python3.10/site-packages/jax/_src/pjit.py", line 1666, in _pjit_call_impl_python
  File "/home/twouters2/miniconda3/envs/jose/lib/python3.10/site-packages/jax/_src/profiler.py", line 336, in wrapper
  File "/home/twouters2/miniconda3/envs/jose/lib/python3.10/site-packages/jax/_src/interpreters/pxla.py", line 1239, in __call__
  File "/home/twouters2/miniconda3/envs/jose/lib/python3.10/site-packages/jax/_src/interpreters/mlir.py", line 2656, in _wrapped_callback
  File "/home/twouters2/miniconda3/envs/jose/lib/python3.10/site-packages/jax/_src/callback.py", line 228, in _callback
  File "/home/twouters2/miniconda3/envs/jose/lib/python3.10/site-packages/jax/_src/callback.py", line 89, in pure_callback_impl
  File "/home/twouters2/miniconda3/envs/jose/lib/python3.10/site-packages/jax/_src/callback.py", line 64, in __call__
  File "/home/twouters2/miniconda3/envs/jose/lib/python3.10/site-packages/equinox/_errors.py", line 89, in raises
_EquinoxRuntimeError: The maximum number of solver steps was reached. Try increasing `max_steps`.


--------------------
An error occurred during the runtime of your JAX program! Unfortunately you do not appear to be using `equinox.filter_jit` (perhaps you are using `jax.jit` instead?) and so further information about the error cannot be displayed. (Probably you are seeing a very large but uninformative error message right now.) Please wrap your program with `equinox.filter_jit`.
--------------------

DONE

JOB STATISTICS
==============
Job ID: 9064133
Cluster: snellius
User/Group: twouters2/twouters2
State: COMPLETED (exit code 0)
Nodes: 1
Cores per node: 18
CPU Utilized: 00:05:16
CPU Efficiency: 6.01% of 01:27:36 core-walltime
Job Wall-clock time: 00:04:52
Memory Utilized: 1.70 GB
Memory Efficiency: 16.97% of 10.00 GB
